<?xml version='1.0'?>
<sdf version="1.6">
    <model name="mast">
        <static>false</static>
        <link name="body">
            <pose>0 0 0.3</pose>
            <collision name="collision">
                <geometry>
                    <mesh>
                        <uri>model://mast/mastNoBar.dae</uri>
                        <scale>1.0  1.0  1.0  </scale>
                    </mesh>
                </geometry>
            </collision>
            <visual name="visual">
                <geometry>
                    <mesh>
                        <uri>model://mast/mastNoBar.dae</uri>
                        <scale>1.0  1.0  1.0  </scale>
                    </mesh>
                </geometry>
                <material>
                    <script>
                        <uri>model://mast/materials/scripts</uri>
                        <uri>model://mast/materials/textures</uri>
                        <name>Beer/Diffuse</name>
                    </script>
                </material>
            </visual>
            <!-- *************Nav Light Visuals/collisions**************** -->
            <visual name="greenLightBase">
                <pose>0.53 -0.04 1.805</pose>
                <geometry>
                    <cylinder>
                        <radius>0.024</radius>
                        <length>0.024</length>
                    </cylinder>
                </geometry>
                <material>
                    <ambient>0 1 0 1</ambient>
                    <diffuse>0 1 0 1</diffuse>
                    <emissive>0 1 0 1</emissive>
                </material>
                <plugin filename="libChangeGreenLightVisual.so" name="changeGreenTop"/>
            </visual>
            <visual name="greenLightTop">
                <pose>0.53 -0.04 1.82</pose>
                <geometry>
                    <sphere>
                        <radius>0.024</radius>
                    </sphere>
                </geometry>
                <material>
                    <ambient>0 1 0 1</ambient>
                    <diffuse>0 1 0 1</diffuse>
                    <emissive>0 1 0 1</emissive>
                </material>
                <plugin filename="libChangeGreenLightVisual.so" name="changeGreenBase"/>
            </visual>
            <collision name="greenLightBase">
                <pose>0.53 -0.04 1.805</pose>
                <geometry>
                    <cylinder>
                        <radius>0.024</radius>
                        <length>0.024</length>
                    </cylinder>
                </geometry>
            </collision>
            <collision name="greenLightTop">
                <pose>0.53 -0.04 1.82</pose>
                <geometry>
                    <sphere>
                        <radius>0.024</radius>
                    </sphere>
                </geometry>
            </collision>
            <visual name="redLightBase">
                <pose>-0.53 -0.04 1.805</pose>
                <geometry>
                    <cylinder>
                        <radius>0.024</radius>
                        <length>0.024</length>
                    </cylinder>
                </geometry>
                <material>
                    <ambient>1 0 0 1</ambient>
                    <diffuse>1 0 0 1</diffuse>
                    <emissive>1 0 0 1</emissive>
                </material>
                <plugin filename="libChangeRedLightVisual.so" name="changeRedBase"/>
            </visual>
            <visual name="redLightTop">
                <pose>-0.53 -0.04 1.82</pose>
                <geometry>
                    <sphere>
                        <radius>0.024</radius>
                    </sphere>
                </geometry>
                <material>
                    <ambient>1 0 0 1</ambient>
                    <diffuse>1 0 0 1</diffuse>
                    <emissive>1 0 0 1</emissive>
                </material>
                <plugin filename="libChangeRedLightVisual.so" name="changeRedTop"/>
            </visual>
            <collision name="redLightBase">
                <pose>-0.53 -0.04 1.805</pose>
                <geometry>
                    <cylinder>
                        <radius>0.024</radius>
                        <length>0.024</length>
                    </cylinder>
                </geometry>
            </collision>
            <collision name="redLightTop">
                <pose>-0.53 -0.04 1.82</pose>
                <geometry>
                    <sphere>
                        <radius>0.024</radius>
                    </sphere>
                </geometry>
            </collision>
            <!-- ***************Nav Light source************** -->
            <light name="greenLight" type="point">
                <attenuation>
                    <range>0.5</range>
                    <linear>0.05</linear>
                </attenuation>
                <specular>0 1 0 1</specular>
                <diffuse>0 1 0 1</diffuse>
                <pose>0.53 -0.04 1.82</pose>
            </light>
            <light name="redLight" type="point">
                <attenuation>
                    <range>0.5</range>
                    <linear>0.05</linear>
                </attenuation>
                <specular>1 0 0 1</specular>
                <diffuse>1 0 0 1</diffuse>
                <pose>-0.53 -0.04 1.82</pose>
            </light>
            <inertial>
                <mass>50</mass>
                <inertia>
                    <ixx>0</ixx>
                    <iyy>0.110208333*50*4</iyy>
                    <izz>0.110208333*50*4</izz>
                    <ixy>0</ixy>
                    <ixz>0</ixz>
                    <iyz>0</iyz>
                </inertia>
            </inertial>
        </link>
        <link name="topBar">
            <pose>0 0.0327 2.44</pose>
            <visual name="spinningBar">
                <geometry>
                    <box>
                        <size>1.15 0.025 0.05</size>
                    </box>
                </geometry>
            </visual>
            <collision name="spinningBar">
                <geometry>
                    <box>
                        <size>1.15 0.025 0.05</size>
                    </box>
                </geometry>
            </collision>
            <inertial>
                <mass>1</mass>
                <inertia>
                    <ixx>0</ixx>
                    <iyy>0.110208333</iyy>
                    <izz>0.110208333</izz>
                    <ixy>0</ixy>
                    <ixz>0</ixz>
                    <iyz>0</iyz>
                </inertia>
            </inertial>
        </link>
        <!-- <model name="base"><static>true</static>-->
        <link name="sphereBase">
            <pose>0 0 0.3</pose>
            <collision name="sphere">
                <geometry>
                    <sphere>
                        <radius>.3</radius>
                    </sphere>
                </geometry>
                <surface>
                    <friction>
                        <ode>
                            <mu>0</mu>
                            <mu2>0</mu2>
                            <slip1>1.0</slip1>
                            <slip2>1.0</slip2>
                        </ode>
                    </friction>
                </surface>
                <pose>0 0 0.1</pose>
            </collision>
            <visual name="sphere">
                <geometry>
                    <sphere>
                        <radius>.3</radius>
                    </sphere>
                </geometry>
                <pose>0 0 0.1</pose>
            </visual>
        </link>
        <link name="base">
            <pose>0 0 0.05</pose>
            <visual name="base">
                <geometry>
                    <box>
                        <size>0.8 0.8 0.1</size>
                    </box>
                </geometry>
            </visual>
            <collision name="base">
                <geometry>
                    <box>
                        <size>0.8 0.8 0.1</size>
                    </box>
                </geometry>
            </collision>
            <inertial>
                <mass>1000</mass>
            </inertial>
        </link>
        <!--   </model>-->
        <joint name="sphereBody" type="prismatic">
            <parent>sphereBase</parent>
            <child>body</child>
            <axis>
                <xyz>0 0 1</xyz>
                <use_parent_model_frame>true</use_parent_model_frame>
                <limit>
                    <lower>0</lower>
                    <upper>0.2</upper>
                </limit>
            </axis>
        </joint>
        <joint name="barSpin" type="revolute">
            <parent>body</parent>
            <child>topBar</child>
            <axis>
                <xyz>0 0 1</xyz>
                <use_parent_model_frame>true</use_parent_model_frame>
            </axis>
            <physics>
                <ode>
                    <velocity>10.0</velocity>
                </ode>
            </physics>
        </joint>
        <!--         <joint name="mastRotation1" type="revolute"><parent>base</parent><child>body</child><axis><xyz>1 0 0</xyz><limit><lower>-0.5</lower><upper>0.5</upper></limit></axis></joint>-->
        <joint name="mastRotation" type="universal">
            <parent>base</parent>
            <child>sphereBase</child>
            <axis>
                <xyz>0 1 0</xyz>
                <limit>
                    <lower>-0.5</lower>
                    <upper>0.5</upper>
                </limit>
                <use_parent_model_frame>true</use_parent_model_frame>
                <dynamics>
                    <friction>2</friction>
                </dynamics>
            </axis>
            <axis2>
                <xyz>1 0 0</xyz>
                <limit>
                    <lower>-0.5</lower>
                    <upper>0.5</upper>
                </limit>
                <use_parent_model_frame>true</use_parent_model_frame>
                <dynamics>
                   <friction>2</friction>
                </dynamics>
            </axis2>
        </joint>
    </model>
</sdf>
